<frozen importlib._bootstrap>:488: DeprecationWarning: Type google.protobuf.pyext._message.ScalarMapContainer uses PyType_Spec with a metaclass that has custom tp_new. This is deprecated and will no longer be allowed in Python 3.14.
<frozen importlib._bootstrap>:488: DeprecationWarning: Type google.protobuf.pyext._message.MessageMapContainer uses PyType_Spec with a metaclass that has custom tp_new. This is deprecated and will no longer be allowed in Python 3.14.
/Users/roneng100/Library/Mobile Documents/com~apple~CloudDocs/Repositories/multimodal-sentiment-analysis-main/Models/DMLAN/src/data_utils.py:46: ResourceWarning: unclosed file <_io.TextIOWrapper name='/Users/roneng100/Datasets/util_models/glove.twitter.27B/glove.twitter.27B.200d.txt' mode='r' encoding='utf-8'>
  word_vec = load_word_vec(fname, word2idx=word2idx)
ResourceWarning: Enable tracemalloc to get the object allocation traceback
Traceback (most recent call last):
  File "/Users/roneng100/Library/Mobile Documents/com~apple~CloudDocs/Repositories/multimodal-sentiment-analysis-main/Models/DMLAN/src/data_utils.py", line 142, in __read_data__
    image = image_process(image_path, transform)
            ^^^^^^^^^^^^^^^^^^^^^^^^^^^^^^^^^^^^
  File "/Users/roneng100/Library/Mobile Documents/com~apple~CloudDocs/Repositories/multimodal-sentiment-analysis-main/Models/DMLAN/src/data_utils.py", line 57, in image_process
    image = Image.open(image_path).convert('RGB')
            ^^^^^^^^^^^^^^^^^^^^^^
  File "/usr/local/Caskroom/miniconda/base/envs/ml/lib/python3.12/site-packages/PIL/Image.py", line 3431, in open
    fp = builtins.open(filename, "rb")
         ^^^^^^^^^^^^^^^^^^^^^^^^^^^^^
FileNotFoundError: [Errno 2] No such file or directory: '/Users/roneng100/Library/Mobile Documents/com~apple~CloudDocs/Repositories/multimodal-sentiment-analysis-main/Users/roneng100/Datasets/MVSA-MTS/images/8.jpg'

During handling of the above exception, another exception occurred:

Traceback (most recent call last):
  File "/Users/roneng100/Library/Mobile Documents/com~apple~CloudDocs/Repositories/multimodal-sentiment-analysis-main/Models/DMLAN/src/train.py", line 71, in <module>
    ins = Instructor(opt)
          ^^^^^^^^^^^^^^^
  File "/Users/roneng100/Library/Mobile Documents/com~apple~CloudDocs/Repositories/multimodal-sentiment-analysis-main/Models/DMLAN/src/instructor.py", line 53, in __init__
    mvsa_dataset = MVSADatasetReader(transform, dataset=opt.dataset, 
                   ^^^^^^^^^^^^^^^^^^^^^^^^^^^^^^^^^^^^^^^^^^^^^^^^^
  File "/Users/roneng100/Library/Mobile Documents/com~apple~CloudDocs/Repositories/multimodal-sentiment-analysis-main/Models/DMLAN/src/data_utils.py", line 190, in __init__
    train_data, train_classes = MVSADatasetReader.__read_data__(
                                ^^^^^^^^^^^^^^^^^^^^^^^^^^^^^^^^
  File "/Users/roneng100/Library/Mobile Documents/com~apple~CloudDocs/Repositories/multimodal-sentiment-analysis-main/Models/DMLAN/src/data_utils.py", line 146, in __read_data__
    image = image_process(image_path_fail, transform)
            ^^^^^^^^^^^^^^^^^^^^^^^^^^^^^^^^^^^^^^^^^
  File "/Users/roneng100/Library/Mobile Documents/com~apple~CloudDocs/Repositories/multimodal-sentiment-analysis-main/Models/DMLAN/src/data_utils.py", line 57, in image_process
    image = Image.open(image_path).convert('RGB')
            ^^^^^^^^^^^^^^^^^^^^^^
  File "/usr/local/Caskroom/miniconda/base/envs/ml/lib/python3.12/site-packages/PIL/Image.py", line 3431, in open
    fp = builtins.open(filename, "rb")
         ^^^^^^^^^^^^^^^^^^^^^^^^^^^^^
FileNotFoundError: [Errno 2] No such file or directory: '/Users/roneng100/Library/Mobile Documents/com~apple~CloudDocs/Repositories/multimodal-sentiment-analysis-main/Users/roneng100/Datasets/MVSA-MTS/images/0default.jpg'
