Traceback (most recent call last):
  File "/home/rgg2706/Multimodal-Sentiment-Analysis/Models/HHMAFM/src/util_tests/data_utils_test.py", line 324, in __read_data__
    image = image_process(image_path, transform)
            ^^^^^^^^^^^^^^^^^^^^^^^^^^^^^^^^^^^^
  File "/home/rgg2706/Multimodal-Sentiment-Analysis/Models/HHMAFM/src/util_tests/data_utils_test.py", line 154, in image_process
    image = Image.open(image_path).convert('RGB')
            ^^^^^^^^^^^^^^^^^^^^^^
  File "/.autofs/tools/spack/var/spack/environments/default-nlp-x86_64-24072401/.spack-env/view/lib/python3.11/site-packages/PIL/Image.py", line 3218, in open
    fp = builtins.open(filename, "rb")
         ^^^^^^^^^^^^^^^^^^^^^^^^^^^^^
FileNotFoundError: [Errno 2] No such file or directory: '/home/rgg2706/Multimodal-Sentiment-Analysis/Datasets/MVSA-MTS/images/73.jpg'

During handling of the above exception, another exception occurred:

Traceback (most recent call last):
  File "/home/rgg2706/Multimodal-Sentiment-Analysis/Models/HHMAFM/src/instructor_tests/train2_test.py", line 205, in <module>
    ins = Instructor(opt)
          ^^^^^^^^^^^^^^^
  File "/home/rgg2706/Multimodal-Sentiment-Analysis/Models/HHMAFM/src/instructor_tests/train2_test.py", line 41, in __init__
    mvsa_dataset = MVSADatasetReader(transform, dataset=opt.dataset, max_seq_len=opt.max_seq_len, path_image=opt.path_image)
                   ^^^^^^^^^^^^^^^^^^^^^^^^^^^^^^^^^^^^^^^^^^^^^^^^^^^^^^^^^^^^^^^^^^^^^^^^^^^^^^^^^^^^^^^^^^^^^^^^^^^^^^^^^
  File "/home/rgg2706/Multimodal-Sentiment-Analysis/Models/HHMAFM/src/util_tests/data_utils_test.py", line 383, in __init__
    self.train_data = MVSADataset(MVSADatasetReader.__read_data__(fname[dataset]['train'], tokenizer, path_image, transform, max_seq_len))
                                  ^^^^^^^^^^^^^^^^^^^^^^^^^^^^^^^^^^^^^^^^^^^^^^^^^^^^^^^^^^^^^^^^^^^^^^^^^^^^^^^^^^^^^^^^^^^^^^^^^^^^^^^
  File "/home/rgg2706/Multimodal-Sentiment-Analysis/Models/HHMAFM/src/util_tests/data_utils_test.py", line 329, in __read_data__
    image = image_process(image_path_fail, transform)
            ^^^^^^^^^^^^^^^^^^^^^^^^^^^^^^^^^^^^^^^^^
  File "/home/rgg2706/Multimodal-Sentiment-Analysis/Models/HHMAFM/src/util_tests/data_utils_test.py", line 154, in image_process
    image = Image.open(image_path).convert('RGB')
            ^^^^^^^^^^^^^^^^^^^^^^
  File "/.autofs/tools/spack/var/spack/environments/default-nlp-x86_64-24072401/.spack-env/view/lib/python3.11/site-packages/PIL/Image.py", line 3218, in open
    fp = builtins.open(filename, "rb")
         ^^^^^^^^^^^^^^^^^^^^^^^^^^^^^
FileNotFoundError: [Errno 2] No such file or directory: 'Datasets/MVSA-MTS/images/0default.jpg'
